Workbook

Sheet cd_dashboard
A1: custom_region_name | B1: council_name | C1: contract_name | D1: contract_dno_regions | E1: work_package_name | F1: capex_bom | G1: capex_installation | H1: capex_connection | I1: target_sites | J1: target_sockets | K1: contingency_percent | L1: target_sockets_1 | M1: target_sockets_2 | N1: target_sockets_3 | O1: target_sockets_4 | P1: target_sockets_5 | Q1: target_sockets_6 | R1: target_sockets_7 | S1: target_sockets_8 | T1: target_sockets_9 | U1: target_sockets_10 | V1: target_sockets_11 | W1: target_sockets_12 | X1: planned_sites | Y1: planned_sockets_1 | Z1: planned_sockets_2 | AA1: planned_sockets_3 | AB1: planned_sockets_4 | AC1: planned_sockets_5 | AD1: planned_sockets_6 | AE1: planned_sockets_7 | AF1: planned_sockets_8 | AG1: planned_sockets_9 | AH1: planned_sockets_10 | AI1: planned_sockets_11 | AJ1: planned_sockets_12
A2: SOUTH | B2: Surrey | C2: Surrey | D2: UKPN_SE | E2: Surrey WP10 | F2: =J2*Assumption!$B$2 -> 150000 | G2: =J2*Assumption!$B$3 -> 150000 | H2: =J2*Assumption!$B$4 -> 150000 | I2: 10 | J2: =SUM(L2:W2) -> 150 | K2: 10 | L2: 50 | M2: 50 | N2: 50 | X2: =SUM(Y2:AJ2) -> 165 | Y2: =ROUND(L2*(100+$K2)/100,0) -> 55 | Z2: =ROUND(M2*(100+$K2)/100,0) -> 55 | AA2: =ROUND(N2*(100+$K2)/100,0) -> 55 | AB2: =ROUND(O2*(100+$K2)/100,0) -> 0 | AC2: =ROUND(P2*(100+$K2)/100,0) -> 0 | AD2: =ROUND(Q2*(100+$K2)/100,0) -> 0 | AE2: =ROUND(R2*(100+$K2)/100,0) -> 0 | AF2: =ROUND(S2*(100+$K2)/100,0) -> 0 | ... AJ2: =ROUND(W2*(100+$K2)/100,0) -> 0
A3: SOUTH | B3: Surrey | C3: Surrey | D3: UKPN_SE | E3: Surrey WP11 | F3: =J3*Assumption!$B$2 -> 100000 | G3: =J3*Assumption!$B$3 -> 100000 | H3: =J3*Assumption!$B$4 -> 100000 | I3: 10 | J3: =SUM(L3:W3) -> 100 | K3: 10 | P3: 50 | Q3: 50 | X3: =SUM(Y3:AJ3) -> 110 | Y3: =ROUND(L3*(100+$K3)/100,0) -> 0 | Z3: 0 | AA3: =ROUND(N3*(100+$K3)/100,0) -> 0 | AB3: =ROUND(O3*(100+$K3)/100,0) -> 0 | AC3: =ROUND(P3*(100+$K3)/100,0) -> 55 | AD3: =ROUND(Q3*(100+$K3)/100,0) -> 55 | AE3: =ROUND(R3*(100+$K3)/100,0) -> 0 | AF3: =ROUND(S3*(100+$K3)/100,0) -> 0 | AG3: =ROUND(T3*(100+$K3)/100,0) -> 0 | AH3: =ROUND(U3*(100+$K3)/100,0) -> 0 | ... AJ3: =ROUND(W3*(100+$K3)/100,0) -> 0
A4: SOUTH | B4: Surrey | C4: Surrey | D4: UKPN_SE | E4: Surrey WP12 | F4: =J4*Assumption!$B$2 -> 100000 | G4: =J4*Assumption!$B$3 -> 100000 | H4: =J4*Assumption!$B$4 -> 100000 | I4: 10 | J4: =SUM(L4:W4) -> 100 | K4: 10 | Q4: 50 | R4: 50 | X4: =SUM(Y4:AJ4) -> 110 | Y4: =ROUND(L4*(100+$K4)/100,0) -> 0 | Z4: 0 | AA4: =ROUND(N4*(100+$K4)/100,0) -> 0 | AB4: =ROUND(O4*(100+$K4)/100,0) -> 0 | AC4: =ROUND(P4*(100+$K4)/100,0) -> 0 | AD4: =ROUND(Q4*(100+$K4)/100,0) -> 55 | AE4: =ROUND(R4*(100+$K4)/100,0) -> 55 | AF4: =ROUND(S4*(100+$K4)/100,0) -> 0 | AG4: =ROUND(T4*(100+$K4)/100,0) -> 0 | AH4: =ROUND(U4*(100+$K4)/100,0) -> 0 | ... AJ4: =ROUND(W4*(100+$K4)/100,0) -> 0
A5: SOUTH | B5: Surrey | C5: Surrey | D5: UKPN_SE | E5: Surrey WP13 | F5: =J5*Assumption!$B$2 -> 100000 | G5: =J5*Assumption!$B$3 -> 100000 | H5: =J5*Assumption!$B$4 -> 100000 | I5: 10 | J5: =SUM(L5:W5) -> 100 | K5: 10 | R5: 50 | S5: 50 | X5: =SUM(Y5:AJ5) -> 110 | Y5: =ROUND(L5*(100+$K5)/100,0) -> 0 | Z5: 0 | AA5: =ROUND(N5*(100+$K5)/100,0) -> 0 | AB5: =ROUND(O5*(100+$K5)/100,0) -> 0 | AC5: =ROUND(P5*(100+$K5)/100,0) -> 0 | AD5: =ROUND(Q5*(100+$K5)/100,0) -> 0 | AE5: =ROUND(R5*(100+$K5)/100,0) -> 55 | AF5: =ROUND(S5*(100+$K5)/100,0) -> 55 | AG5: =ROUND(T5*(100+$K5)/100,0) -> 0 | AH5: =ROUND(U5*(100+$K5)/100,0) -> 0 | ... AJ5: =ROUND(W5*(100+$K5)/100,0) -> 0
A6: SOUTH | B6: Surrey | C6: Surrey | D6: UKPN_SE | E6: Surrey WP14 | F6: =J6*Assumption!$B$2 -> 100000 | G6: =J6*Assumption!$B$3 -> 100000 | H6: =J6*Assumption!$B$4 -> 100000 | I6: 10 | J6: =SUM(L6:W6) -> 100 | K6: 10 | S6: 50 | T6: 50 | X6: =SUM(Y6:AJ6) -> 110 | Y6: =ROUND(L6*(100+$K6)/100,0) -> 0 | Z6: 0 | AA6: =ROUND(N6*(100+$K6)/100,0) -> 0 | AB6: =ROUND(O6*(100+$K6)/100,0) -> 0 | AC6: =ROUND(P6*(100+$K6)/100,0) -> 0 | AD6: =ROUND(Q6*(100+$K6)/100,0) -> 0 | AE6: =ROUND(R6*(100+$K6)/100,0) -> 0 | AF6: =ROUND(S6*(100+$K6)/100,0) -> 55 | AG6: =ROUND(T6*(100+$K6)/100,0) -> 55 | AH6: =ROUND(U6*(100+$K6)/100,0) -> 0 | ... AJ6: =ROUND(W6*(100+$K6)/100,0) -> 0
A7: SOUTH | B7: Surrey | C7: Surrey | D7: UKPN_SE | E7: Surrey WP15 | F7: =J7*Assumption!$B$2 -> 100000 | G7: =J7*Assumption!$B$3 -> 100000 | H7: =J7*Assumption!$B$4 -> 100000 | I7: 10 | J7: =SUM(L7:W7) -> 100 | K7: 10 | U7: 50 | V7: 50 | X7: =SUM(Y7:AJ7) -> 110 | Y7: =ROUND(L7*(100+$K7)/100,0) -> 0 | Z7: 0 | AA7: =ROUND(N7*(100+$K7)/100,0) -> 0 | AB7: =ROUND(O7*(100+$K7)/100,0) -> 0 | AC7: =ROUND(P7*(100+$K7)/100,0) -> 0 | AD7: =ROUND(Q7*(100+$K7)/100,0) -> 0 | AE7: =ROUND(R7*(100+$K7)/100,0) -> 0 | AF7: =ROUND(S7*(100+$K7)/100,0) -> 0 | AG7: =ROUND(T7*(100+$K7)/100,0) -> 0 | AH7: =ROUND(U7*(100+$K7)/100,0) -> 55 | ... AJ7: =ROUND(W7*(100+$K7)/100,0) -> 0
A8: SOUTH | B8: Surrey | C8: Surrey | D8: UKPN_SE | E8: Surrey WP16 | F8: =J8*Assumption!$B$2 -> 50000 | G8: =J8*Assumption!$B$3 -> 50000 | H8: =J8*Assumption!$B$4 -> 50000 | I8: 10 | J8: =SUM(L8:W8) -> 50 | K8: 10 | W8: 50 | X8: =SUM(Y8:AJ8) -> 55 | Y8: =ROUND(L8*(100+$K8)/100,0) -> 0 | Z8: 0 | AA8: =ROUND(N8*(100+$K8)/100,0) -> 0 | AB8: =ROUND(O8*(100+$K8)/100,0) -> 0 | AC8: =ROUND(P8*(100+$K8)/100,0) -> 0 | AD8: =ROUND(Q8*(100+$K8)/100,0) -> 0 | AE8: =ROUND(R8*(100+$K8)/100,0) -> 0 | AF8: =ROUND(S8*(100+$K8)/100,0) -> 0 | AG8: =ROUND(T8*(100+$K8)/100,0) -> 0 | AH8: =ROUND(U8*(100+$K8)/100,0) -> 0 | ... AJ8: =ROUND(W8*(100+$K8)/100,0) -> 55
A9: SOUTH | B9: Surrey | C9: Surrey | D9: UKPN_SE | E9: Surrey WP17 | F9: =J9*Assumption!$B$2 -> 0 | G9: =J9*Assumption!$B$3 -> 0 | H9: =J9*Assumption!$B$4 -> 0 | I9: 10 | J9: =SUM(L9:W9) -> 0 | K9: 10 | X9: =SUM(Y9:AJ9) -> 0 | Y9: =ROUND(L9*(100+$K9)/100,0) -> 0 | Z9: 0 | AA9: =ROUND(N9*(100+$K9)/100,0) -> 0 | AB9: =ROUND(O9*(100+$K9)/100,0) -> 0 | AC9: =ROUND(P9*(100+$K9)/100,0) -> 0 | AD9: =ROUND(Q9*(100+$K9)/100,0) -> 0 | AE9: =ROUND(R9*(100+$K9)/100,0) -> 0 | AF9: =ROUND(S9*(100+$K9)/100,0) -> 0 | AG9: =ROUND(T9*(100+$K9)/100,0) -> 0 | AH9: =ROUND(U9*(100+$K9)/100,0) -> 0 | ... AJ9: =ROUND(W9*(100+$K9)/100,0) -> 0
A10: SOUTH | B10: Surrey | C10: Surrey | D10: UKPN_SE | E10: Surrey WP18 | F10: =J10*Assumption!$B$2 -> 0 | G10: =J10*Assumption!$B$3 -> 0 | H10: =J10*Assumption!$B$4 -> 0 | I10: 10 | J10: =SUM(L10:W10) -> 0 | K10: 10 | X10: =SUM(Y10:AJ10) -> 0 | Y10: =ROUND(L10*(100+$K10)/100,0) -> 0 | Z10: 0 | AA10: =ROUND(N10*(100+$K10)/100,0) -> 0 | AB10: =ROUND(O10*(100+$K10)/100,0) -> 0 | AC10: =ROUND(P10*(100+$K10)/100,0) -> 0 | AD10: =ROUND(Q10*(100+$K10)/100,0) -> 0 | AE10: =ROUND(R10*(100+$K10)/100,0) -> 0 | AF10: =ROUND(S10*(100+$K10)/100,0) -> 0 | AG10: =ROUND(T10*(100+$K10)/100,0) -> 0 | AH10: =ROUND(U10*(100+$K10)/100,0) -> 0 | ... AJ10: =ROUND(W10*(100+$K10)/100,0) -> 0
A11: SOUTH | B11: Surrey | C11: Surrey | D11: UKPN_SE | E11: Surrey WP19 | F11: =J11*Assumption!$B$2 -> 0 | G11: =J11*Assumption!$B$3 -> 0 | H11: =J11*Assumption!$B$4 -> 0 | I11: 10 | J11: =SUM(L11:W11) -> 0 | K11: 10 | X11: =SUM(Y11:AJ11) -> 0 | Y11: =ROUND(L11*(100+$K11)/100,0) -> 0 | Z11: 0 | AA11: =ROUND(N11*(100+$K11)/100,0) -> 0 | AB11: =ROUND(O11*(100+$K11)/100,0) -> 0 | AC11: =ROUND(P11*(100+$K11)/100,0) -> 0 | AD11: =ROUND(Q11*(100+$K11)/100,0) -> 0 | AE11: =ROUND(R11*(100+$K11)/100,0) -> 0 | AF11: =ROUND(S11*(100+$K11)/100,0) -> 0 | AG11: =ROUND(T11*(100+$K11)/100,0) -> 0 | AH11: =ROUND(U11*(100+$K11)/100,0) -> 0 | ... AJ11: =ROUND(W11*(100+$K11)/100,0) -> 0
A12: SOUTH | B12: Surrey | C12: Surrey | D12: UKPN_SE | E12: Surrey WP20 | F12: =J12*Assumption!$B$2 -> 0 | G12: =J12*Assumption!$B$3 -> 0 | H12: =J12*Assumption!$B$4 -> 0 | I12: 10 | J12: =SUM(L12:W12) -> 0 | K12: 10 | X12: =SUM(Y12:AJ12) -> 0 | Y12: =ROUND(L12*(100+$K12)/100,0) -> 0 | Z12: 0 | AA12: =ROUND(N12*(100+$K12)/100,0) -> 0 | AB12: =ROUND(O12*(100+$K12)/100,0) -> 0 | AC12: =ROUND(P12*(100+$K12)/100,0) -> 0 | AD12: =ROUND(Q12*(100+$K12)/100,0) -> 0 | AE12: =ROUND(R12*(100+$K12)/100,0) -> 0 | AF12: =ROUND(S12*(100+$K12)/100,0) -> 0 | AG12: =ROUND(T12*(100+$K12)/100,0) -> 0 | AH12: =ROUND(U12*(100+$K12)/100,0) -> 0 | ... AJ12: =ROUND(W12*(100+$K12)/100,0) -> 0
A13: SOUTH | B13: Surrey | C13: Surrey | D13: UKPN_SE | E13: Surrey WP21 | F13: =J13*Assumption!$B$2 -> 0 | G13: =J13*Assumption!$B$3 -> 0 | H13: =J13*Assumption!$B$4 -> 0 | I13: 10 | J13: =SUM(L13:W13) -> 0 | K13: 10 | X13: =SUM(Y13:AJ13) -> 0 | Y13: =ROUND(L13*(100+$K13)/100,0) -> 0 | Z13: 0 | AA13: =ROUND(N13*(100+$K13)/100,0) -> 0 | AB13: =ROUND(O13*(100+$K13)/100,0) -> 0 | AC13: =ROUND(P13*(100+$K13)/100,0) -> 0 | AD13: =ROUND(Q13*(100+$K13)/100,0) -> 0 | AE13: =ROUND(R13*(100+$K13)/100,0) -> 0 | AF13: =ROUND(S13*(100+$K13)/100,0) -> 0 | AG13: =ROUND(T13*(100+$K13)/100,0) -> 0 | AH13: =ROUND(U13*(100+$K13)/100,0) -> 0 | ... AJ13: =ROUND(W13*(100+$K13)/100,0) -> 0
A14: SOUTH | B14: Surrey | C14: Surrey | D14: UKPN_SE | E14: Surrey WP22 | F14: =J14*Assumption!$B$2 -> 0 | G14: =J14*Assumption!$B$3 -> 0 | H14: =J14*Assumption!$B$4 -> 0 | I14: 10 | J14: =SUM(L14:W14) -> 0 | K14: 10 | X14: =SUM(Y14:AJ14) -> 0 | Y14: =ROUND(L14*(100+$K14)/100,0) -> 0 | Z14: 0 | AA14: =ROUND(N14*(100+$K14)/100,0) -> 0 | AB14: =ROUND(O14*(100+$K14)/100,0) -> 0 | AC14: =ROUND(P14*(100+$K14)/100,0) -> 0 | AD14: =ROUND(Q14*(100+$K14)/100,0) -> 0 | AE14: =ROUND(R14*(100+$K14)/100,0) -> 0 | AF14: =ROUND(S14*(100+$K14)/100,0) -> 0 | AG14: =ROUND(T14*(100+$K14)/100,0) -> 0 | AH14: =ROUND(U14*(100+$K14)/100,0) -> 0 | ... AJ14: =ROUND(W14*(100+$K14)/100,0) -> 0
A15: SOUTH | B15: Surrey LP | C15: Surrey LP | D15: UKPN_SE | E15: Surrey Lamppost WP1 | F15: =J15*Assumption!$B$2 -> 100000 | G15: =J15*Assumption!$B$3 -> 100000 | H15: =J15*Assumption!$B$4 -> 100000 | I15: 10 | J15: =SUM(L15:W15) -> 100 | K15: 10 | O15: 50 | P15: 50 | X15: =SUM(Y15:AJ15) -> 110 | Y15: =ROUND(L15*(100+$K15)/100,0) -> 0 | Z15: 0 | AA15: =ROUND(N15*(100+$K15)/100,0) -> 0 | AB15: =ROUND(O15*(100+$K15)/100,0) -> 55 | AC15: =ROUND(P15*(100+$K15)/100,0) -> 55 | AD15: =ROUND(Q15*(100+$K15)/100,0) -> 0 | AE15: =ROUND(R15*(100+$K15)/100,0) -> 0 | AF15: =ROUND(S15*(100+$K15)/100,0) -> 0 | AG15: =ROUND(T15*(100+$K15)/100,0) -> 0 | AH15: =ROUND(U15*(100+$K15)/100,0) -> 0 | ... AJ15: =ROUND(W15*(100+$K15)/100,0) -> 0
A16: SOUTH | B16: Surrey LP | C16: Surrey LP | D16: UKPN_SE | E16: Surrey Lamppost WP2 | F16: =J16*Assumption!$B$2 -> 300000 | G16: =J16*Assumption!$B$3 -> 300000 | H16: =J16*Assumption!$B$4 -> 300000 | I16: 10 | J16: =SUM(L16:W16) -> 300 | K16: 10 | Q16: 50 | R16: 50 | S16: 50 | T16: 50 | U16: 50 | V16: 50 | X16: =SUM(Y16:AJ16) -> 330 | Y16: =ROUND(L16*(100+$K16)/100,0) -> 0 | Z16: 0 | AA16: =ROUND(N16*(100+$K16)/100,0) -> 0 | AB16: =ROUND(O16*(100+$K16)/100,0) -> 0 | AC16: =ROUND(P16*(100+$K16)/100,0) -> 0 | AD16: =ROUND(Q16*(100+$K16)/100,0) -> 55 | AE16: =ROUND(R16*(100+$K16)/100,0) -> 55 | AF16: =ROUND(S16*(100+$K16)/100,0) -> 55 | AG16: =ROUND(T16*(100+$K16)/100,0) -> 55 | AH16: =ROUND(U16*(100+$K16)/100,0) -> 55 | ... AJ16: =ROUND(W16*(100+$K16)/100,0) -> 0
A17: SOUTH | B17: Surrey LP | C17: Surrey LP | D17: UKPN_SE | E17: Surrey Lamppost WP3 | F17: =J17*Assumption!$B$2 -> 100000 | G17: =J17*Assumption!$B$3 -> 100000 | H17: =J17*Assumption!$B$4 -> 100000 | I17: 10 | J17: =SUM(L17:W17) -> 100 | K17: 10 | Q17: 50 | R17: 50 | X17: =SUM(Y17:AJ17) -> 110 | Y17: =ROUND(L17*(100+$K17)/100,0) -> 0 | Z17: 0 | AA17: =ROUND(N17*(100+$K17)/100,0) -> 0 | AB17: =ROUND(O17*(100+$K17)/100,0) -> 0 | AC17: =ROUND(P17*(100+$K17)/100,0) -> 0 | AD17: =ROUND(Q17*(100+$K17)/100,0) -> 55 | AE17: =ROUND(R17*(100+$K17)/100,0) -> 55 | AF17: =ROUND(S17*(100+$K17)/100,0) -> 0 | AG17: =ROUND(T17*(100+$K17)/100,0) -> 0 | AH17: =ROUND(U17*(100+$K17)/100,0) -> 0 | ... AJ17: =ROUND(W17*(100+$K17)/100,0) -> 0
A18: SOUTH | B18: Surrey LP | C18: Surrey LP | D18: UKPN_SE | E18: Surrey Lamppost WP4 | F18: =J18*Assumption!$B$2 -> 100000 | G18: =J18*Assumption!$B$3 -> 100000 | H18: =J18*Assumption!$B$4 -> 100000 | I18: 10 | J18: =SUM(L18:W18) -> 100 | K18: 10 | R18: 50 | S18: 50 | X18: =SUM(Y18:AJ18) -> 110 | Y18: =ROUND(L18*(100+$K18)/100,0) -> 0 | Z18: 0 | AA18: =ROUND(N18*(100+$K18)/100,0) -> 0 | AB18: =ROUND(O18*(100+$K18)/100,0) -> 0 | AC18: =ROUND(P18*(100+$K18)/100,0) -> 0 | AD18: =ROUND(Q18*(100+$K18)/100,0) -> 0 | AE18: =ROUND(R18*(100+$K18)/100,0) -> 55 | AF18: =ROUND(S18*(100+$K18)/100,0) -> 55 | AG18: =ROUND(T18*(100+$K18)/100,0) -> 0 | AH18: =ROUND(U18*(100+$K18)/100,0) -> 0 | ... AJ18: =ROUND(W18*(100+$K18)/100,0) -> 0
A19: SOUTH | B19: Surrey LP | C19: Surrey LP | D19: UKPN_SE | E19: Surrey Lamppost WP5 | F19: =J19*Assumption!$B$2 -> 100000 | G19: =J19*Assumption!$B$3 -> 100000 | H19: =J19*Assumption!$B$4 -> 100000 | I19: 10 | J19: =SUM(L19:W19) -> 100 | K19: 10 | S19: 50 | T19: 50 | X19: =SUM(Y19:AJ19) -> 110 | Y19: =ROUND(L19*(100+$K19)/100,0) -> 0 | Z19: 0 | AA19: =ROUND(N19*(100+$K19)/100,0) -> 0 | AB19: =ROUND(O19*(100+$K19)/100,0) -> 0 | AC19: =ROUND(P19*(100+$K19)/100,0) -> 0 | AD19: =ROUND(Q19*(100+$K19)/100,0) -> 0 | AE19: =ROUND(R19*(100+$K19)/100,0) -> 0 | AF19: =ROUND(S19*(100+$K19)/100,0) -> 55 | AG19: =ROUND(T19*(100+$K19)/100,0) -> 55 | AH19: =ROUND(U19*(100+$K19)/100,0) -> 0 | ... AJ19: =ROUND(W19*(100+$K19)/100,0) -> 0
A20: SOUTH | B20: Surrey LP | C20: Surrey LP | D20: UKPN_SE | E20: Surrey Lamppost WP6 | F20: =J20*Assumption!$B$2 -> 100000 | G20: =J20*Assumption!$B$3 -> 100000 | H20: =J20*Assumption!$B$4 -> 100000 | I20: 10 | J20: =SUM(L20:W20) -> 100 | K20: 10 | T20: 50 | U20: 50 | X20: =SUM(Y20:AJ20) -> 110 | Y20: =ROUND(L20*(100+$K20)/100,0) -> 0 | Z20: 0 | AA20: =ROUND(N20*(100+$K20)/100,0) -> 0 | AB20: =ROUND(O20*(100+$K20)/100,0) -> 0 | AC20: =ROUND(P20*(100+$K20)/100,0) -> 0 | AD20: =ROUND(Q20*(100+$K20)/100,0) -> 0 | AE20: =ROUND(R20*(100+$K20)/100,0) -> 0 | AF20: =ROUND(S20*(100+$K20)/100,0) -> 0 | AG20: =ROUND(T20*(100+$K20)/100,0) -> 55 | AH20: =ROUND(U20*(100+$K20)/100,0) -> 55 | ... AJ20: =ROUND(W20*(100+$K20)/100,0) -> 0
A21: SOUTH | B21: Surrey LP | C21: Surrey LP | D21: UKPN_SE | E21: Surrey Lamppost WP7 | F21: =J21*Assumption!$B$2 -> 100000 | G21: =J21*Assumption!$B$3 -> 100000 | H21: =J21*Assumption!$B$4 -> 100000 | I21: 10 | J21: =SUM(L21:W21) -> 100 | K21: 10 | U21: 50 | V21: 50 | X21: =SUM(Y21:AJ21) -> 110 | Y21: =ROUND(L21*(100+$K21)/100,0) -> 0 | Z21: 0 | AA21: =ROUND(N21*(100+$K21)/100,0) -> 0 | AB21: =ROUND(O21*(100+$K21)/100,0) -> 0 | AC21: =ROUND(P21*(100+$K21)/100,0) -> 0 | AD21: =ROUND(Q21*(100+$K21)/100,0) -> 0 | AE21: =ROUND(R21*(100+$K21)/100,0) -> 0 | AF21: =ROUND(S21*(100+$K21)/100,0) -> 0 | AG21: =ROUND(T21*(100+$K21)/100,0) -> 0 | AH21: =ROUND(U21*(100+$K21)/100,0) -> 55 | ... AJ21: =ROUND(W21*(100+$K21)/100,0) -> 0
A22: SOUTH | B22: Surrey LP | C22: Surrey LP | D22: UKPN_SE | E22: Surrey Lamppost WP8 | F22: =J22*Assumption!$B$2 -> 100000 | G22: =J22*Assumption!$B$3 -> 100000 | H22: =J22*Assumption!$B$4 -> 100000 | I22: 10 | J22: =SUM(L22:W22) -> 100 | K22: 10 | V22: 50 | W22: 50 | X22: =SUM(Y22:AJ22) -> 110 | Y22: =ROUND(L22*(100+$K22)/100,0) -> 0 | Z22: 0 | AA22: =ROUND(N22*(100+$K22)/100,0) -> 0 | AB22: =ROUND(O22*(100+$K22)/100,0) -> 0 | AC22: =ROUND(P22*(100+$K22)/100,0) -> 0 | AD22: =ROUND(Q22*(100+$K22)/100,0) -> 0 | AE22: =ROUND(R22*(100+$K22)/100,0) -> 0 | AF22: =ROUND(S22*(100+$K22)/100,0) -> 0 | AG22: =ROUND(T22*(100+$K22)/100,0) -> 0 | AH22: =ROUND(U22*(100+$K22)/100,0) -> 0 | ... AJ22: =ROUND(W22*(100+$K22)/100,0) -> 55
A23: SOUTH | B23: Surrey LP | C23: Surrey LP | D23: UKPN_SE | E23: Surrey Lamppost WP9 | F23: =J23*Assumption!$B$2 -> 50000 | G23: =J23*Assumption!$B$3 -> 50000 | H23: =J23*Assumption!$B$4 -> 50000 | I23: 10 | J23: =SUM(L23:W23) -> 50 | K23: 10 | W23: 50 | X23: =SUM(Y23:AJ23) -> 55 | Y23: =ROUND(L23*(100+$K23)/100,0) -> 0 | Z23: 0 | AA23: =ROUND(N23*(100+$K23)/100,0) -> 0 | AB23: =ROUND(O23*(100+$K23)/100,0) -> 0 | AC23: =ROUND(P23*(100+$K23)/100,0) -> 0 | AD23: =ROUND(Q23*(100+$K23)/100,0) -> 0 | AE23: =ROUND(R23*(100+$K23)/100,0) -> 0 | AF23: =ROUND(S23*(100+$K23)/100,0) -> 0 | AG23: =ROUND(T23*(100+$K23)/100,0) -> 0 | AH23: =ROUND(U23*(100+$K23)/100,0) -> 0 | ... AJ23: =ROUND(W23*(100+$K23)/100,0) -> 55
A24: SOUTH | B24: Surrey LP | C24: Surrey LP | D24: UKPN_SE | E24: Surrey Lamppost WP10 | F24: 0 | G24: =J24*Assumption!$B$3 -> 0 | H24: =J24*Assumption!$B$4 -> 0 | I24: 10 | J24: =SUM(L24:W24) -> 0 | K24: 10 | X24: =SUM(Y24:AJ24) -> 0 | Y24: =ROUND(L24*(100+$K24)/100,0) -> 0 | Z24: 0 | AA24: =ROUND(N24*(100+$K24)/100,0) -> 0 | AB24: =ROUND(O24*(100+$K24)/100,0) -> 0 | AC24: =ROUND(P24*(100+$K24)/100,0) -> 0 | AD24: =ROUND(Q24*(100+$K24)/100,0) -> 0 | AE24: =ROUND(R24*(100+$K24)/100,0) -> 0 | AF24: =ROUND(S24*(100+$K24)/100,0) -> 0 | AG24: =ROUND(T24*(100+$K24)/100,0) -> 0 | AH24: =ROUND(U24*(100+$K24)/100,0) -> 0 | ... AJ24: =ROUND(W24*(100+$K24)/100,0) -> 0
A25: SOUTH | B25: Surrey LP | C25: Surrey LP | D25: UKPN_SE | E25: Surrey Lamppost WP11 | F25: 0 | G25: =J25*Assumption!$B$3 -> 0 | H25: =J25*Assumption!$B$4 -> 0 | I25: 10 | J25: =SUM(L25:W25) -> 0 | K25: 10 | X25: =SUM(Y25:AJ25) -> 0 | Y25: =ROUND(L25*(100+$K25)/100,0) -> 0 | Z25: 0 | AA25: =ROUND(N25*(100+$K25)/100,0) -> 0 | AB25: =ROUND(O25*(100+$K25)/100,0) -> 0 | AC25: =ROUND(P25*(100+$K25)/100,0) -> 0 | AD25: =ROUND(Q25*(100+$K25)/100,0) -> 0 | AE25: =ROUND(R25*(100+$K25)/100,0) -> 0 | AF25: =ROUND(S25*(100+$K25)/100,0) -> 0 | AG25: =ROUND(T25*(100+$K25)/100,0) -> 0 | AH25: =ROUND(U25*(100+$K25)/100,0) -> 0 | ... AJ25: =ROUND(W25*(100+$K25)/100,0) -> 0
A26: SOUTH | B26: Plymouth | C26: Plymouth | D26: WPD_S | E26: Plymouth WP1 | F26: 111000 | G26: =J26*Assumption!$B$3 -> 50000 | H26: =J26*Assumption!$B$4 -> 50000 | I26: 10 | J26: =SUM(L26:W26) -> 50 | K26: 10 | L26: 0 | M26: 0 | N26: 0 | O26: 50 | P26: 0 | Q26: 0 | R26: 0 | S26: 0 | T26: 0 | U26: 0 | V26: 0 | W26: 0 | X26: =SUM(Y26:AJ26) -> 55 | Y26: =ROUND(L26*(100+$K26)/100,0) -> 0 | Z26: 0 | AA26: =ROUND(N26*(100+$K26)/100,0) -> 0 | AB26: =ROUND(O26*(100+$K26)/100,0) -> 55 | AC26: =ROUND(P26*(100+$K26)/100,0) -> 0 | AD26: =ROUND(Q26*(100+$K26)/100,0) -> 0 | AE26: =ROUND(R26*(100+$K26)/100,0) -> 0 | AF26: =ROUND(S26*(100+$K26)/100,0) -> 0 | AG26: =ROUND(T26*(100+$K26)/100,0) -> 0 | AH26: =ROUND(U26*(100+$K26)/100,0) -> 0 | ... AJ26: =ROUND(W26*(100+$K26)/100,0) -> 0
A27: SOUTH | B27: Plymouth | C27: Plymouth | D27: WPD_S | E27: Plymouth WP2 | F27: 111000 | G27: =J27*Assumption!$B$3 -> 100000 | H27: =J27*Assumption!$B$4 -> 100000 | I27: 10 | J27: =SUM(L27:W27) -> 100 | K27: 10 | L27: 0 | M27: 0 | N27: 0 | O27: 0 | P27: 50 | Q27: 50 | R27: 0 | S27: 0 | T27: 0 | U27: 0 | V27: 0 | W27: 0 | X27: =SUM(Y27:AJ27) -> 110 | Y27: =ROUND(L27*(100+$K27)/100,0) -> 0 | Z27: 0 | AA27: =ROUND(N27*(100+$K27)/100,0) -> 0 | AB27: =ROUND(O27*(100+$K27)/100,0) -> 0 | AC27: =ROUND(P27*(100+$K27)/100,0) -> 55 | AD27: =ROUND(Q27*(100+$K27)/100,0) -> 55 | AE27: =ROUND(R27*(100+$K27)/100,0) -> 0 | AF27: =ROUND(S27*(100+$K27)/100,0) -> 0 | AG27: =ROUND(T27*(100+$K27)/100,0) -> 0 | AH27: =ROUND(U27*(100+$K27)/100,0) -> 0 | ... AJ27: =ROUND(W27*(100+$K27)/100,0) -> 0
A28: SOUTH | B28: Plymouth | C28: Plymouth | D28: WPD_S | E28: Plymouth WP3 | F28: 150000 | G28: =J28*Assumption!$B$3 -> 150000 | H28: =J28*Assumption!$B$4 -> 150000 | I28: 10 | J28: =SUM(L28:W28) -> 150 | K28: 10 | L28: 0 | M28: 0 | N28: 0 | O28: 0 | P28: 0 | Q28: 0 | R28: 50 | S28: 50 | T28: 50 | U28: 0 | V28: 0 | W28: 0 | X28: =SUM(Y28:AJ28) -> 165 | Y28: =ROUND(L28*(100+$K28)/100,0) -> 0 | Z28: 0 | AA28: =ROUND(N28*(100+$K28)/100,0) -> 0 | AB28: =ROUND(O28*(100+$K28)/100,0) -> 0 | AC28: =ROUND(P28*(100+$K28)/100,0) -> 0 | AD28: =ROUND(Q28*(100+$K28)/100,0) -> 0 | AE28: =ROUND(R28*(100+$K28)/100,0) -> 55 | AF28: =ROUND(S28*(100+$K28)/100,0) -> 55 | AG28: =ROUND(T28*(100+$K28)/100,0) -> 55 | AH28: =ROUND(U28*(100+$K28)/100,0) -> 0 | ... AJ28: =ROUND(W28*(100+$K28)/100,0) -> 0
A29: SOUTH | B29: Plymouth | C29: Plymouth | D29: WPD_S | E29: Plymouth WP4 | F29: 150000 | G29: =J29*Assumption!$B$3 -> 150000 | H29: =J29*Assumption!$B$4 -> 150000 | I29: 10 | J29: =SUM(L29:W29) -> 150 | K29: 10 | L29: 0 | M29: 0 | N29: 0 | O29: 0 | P29: 0 | Q29: 0 | R29: 0 | S29: 0 | T29: 50 | U29: 50 | V29: 50 | W29: 0 | X29: =SUM(Y29:AJ29) -> 165 | Y29: =ROUND(L29*(100+$K29)/100,0) -> 0 | Z29: 0 | AA29: =ROUND(N29*(100+$K29)/100,0) -> 0 | AB29: =ROUND(O29*(100+$K29)/100,0) -> 0 | AC29: =ROUND(P29*(100+$K29)/100,0) -> 0 | AD29: =ROUND(Q29*(100+$K29)/100,0) -> 0 | AE29: =ROUND(R29*(100+$K29)/100,0) -> 0 | AF29: =ROUND(S29*(100+$K29)/100,0) -> 0 | AG29: =ROUND(T29*(100+$K29)/100,0) -> 55 | AH29: =ROUND(U29*(100+$K29)/100,0) -> 55 | ... AJ29: =ROUND(W29*(100+$K29)/100,0) -> 0
A30: SOUTH | B30: Plymouth | C30: Plymouth | D30: WPD_S | E30: Plymouth WP5 | F30: 30000 | G30: =J30*Assumption!$B$3 -> 50000 | H30: =J30*Assumption!$B$4 -> 50000 | I30: 10 | J30: =SUM(L30:W30) -> 50 | K30: 10 | L30: 0 | M30: 0 | N30: 0 | O30: 0 | P30: 0 | Q30: 0 | R30: 0 | S30: 0 | T30: 0 | U30: 0 | V30: 0 | W30: 50 | X30: =SUM(Y30:AJ30) -> 55 | Y30: =ROUND(L30*(100+$K30)/100,0) -> 0 | Z30: 0 | AA30: =ROUND(N30*(100+$K30)/100,0) -> 0 | AB30: =ROUND(O30*(100+$K30)/100,0) -> 0 | AC30: =ROUND(P30*(100+$K30)/100,0) -> 0 | AD30: =ROUND(Q30*(100+$K30)/100,0) -> 0 | AE30: =ROUND(R30*(100+$K30)/100,0) -> 0 | AF30: =ROUND(S30*(100+$K30)/100,0) -> 0 | AG30: =ROUND(T30*(100+$K30)/100,0) -> 0 | AH30: =ROUND(U30*(100+$K30)/100,0) -> 0 | ... AJ30: =ROUND(W30*(100+$K30)/100,0) -> 55
A31: SOUTH | B31: Bournemouth, Christchurch & Poole | C31: Bournemouth, Christchurch & Poole | D31: WPD_S | E31: Bournemouth, Christchurch and Poole WP1 | F31: 195000 | G31: =J31*Assumption!$B$3 -> 200000 | H31: =J31*Assumption!$B$4 -> 200000 | I31: 10 | J31: =SUM(L31:W31) -> 200 | K31: 10 | T31: 50 | U31: 50 | V31: 50 | W31: 50 | X31: =SUM(Y31:AJ31) -> 220 | Y31: =ROUND(L31*(100+$K31)/100,0) -> 0 | Z31: 0 | AA31: =ROUND(N31*(100+$K31)/100,0) -> 0 | AB31: =ROUND(O31*(100+$K31)/100,0) -> 0 | AC31: =ROUND(P31*(100+$K31)/100,0) -> 0 | AD31: =ROUND(Q31*(100+$K31)/100,0) -> 0 | AE31: =ROUND(R31*(100+$K31)/100,0) -> 0 | AF31: =ROUND(S31*(100+$K31)/100,0) -> 0 | AG31: =ROUND(T31*(100+$K31)/100,0) -> 55 | AH31: =ROUND(U31*(100+$K31)/100,0) -> 55 | ... AJ31: =ROUND(W31*(100+$K31)/100,0) -> 55
A32: SOUTH | B32: Bournemouth, Christchurch & Poole | C32: Bournemouth, Christchurch & Poole | D32: WPD_S | E32: Bournemouth, Christchurch and Poole WP2 | F32: 0 | G32: =J32*Assumption!$B$3 -> 0 | H32: =J32*Assumption!$B$4 -> 0 | I32: 10 | J32: =SUM(L32:W32) -> 0 | K32: 10 | X32: =SUM(Y32:AJ32) -> 0 | Y32: =ROUND(L32*(100+$K32)/100,0) -> 0 | Z32: 0 | AA32: =ROUND(N32*(100+$K32)/100,0) -> 0 | AB32: =ROUND(O32*(100+$K32)/100,0) -> 0 | AC32: =ROUND(P32*(100+$K32)/100,0) -> 0 | AD32: =ROUND(Q32*(100+$K32)/100,0) -> 0 | AE32: =ROUND(R32*(100+$K32)/100,0) -> 0 | AF32: =ROUND(S32*(100+$K32)/100,0) -> 0 | AG32: =ROUND(T32*(100+$K32)/100,0) -> 0 | AH32: =ROUND(U32*(100+$K32)/100,0) -> 0 | ... AJ32: =ROUND(W32*(100+$K32)/100,0) -> 0
A33: SOUTH | B33: Bournemouth, Christchurch & Poole | C33: Bournemouth, Christchurch & Poole | D33: WPD_S | E33: Bournemouth, Christchurch and Poole WP3 | F33: 0 | G33: =J33*Assumption!$B$3 -> 0 | H33: =J33*Assumption!$B$4 -> 0 | I33: 10 | J33: =SUM(L33:W33) -> 0 | K33: 10 | X33: =SUM(Y33:AJ33) -> 0 | Y33: =ROUND(L33*(100+$K33)/100,0) -> 0 | Z33: 0 | AA33: =ROUND(N33*(100+$K33)/100,0) -> 0 | AB33: =ROUND(O33*(100+$K33)/100,0) -> 0 | AC33: =ROUND(P33*(100+$K33)/100,0) -> 0 | AD33: =ROUND(Q33*(100+$K33)/100,0) -> 0 | AE33: =ROUND(R33*(100+$K33)/100,0) -> 0 | AF33: =ROUND(S33*(100+$K33)/100,0) -> 0 | AG33: =ROUND(T33*(100+$K33)/100,0) -> 0 | AH33: =ROUND(U33*(100+$K33)/100,0) -> 0 | ... AJ33: =ROUND(W33*(100+$K33)/100,0) -> 0
A34: SOUTH | B34: Dorset | C34: Dorset | D34: WPD_S | E34: Dorset WP1 | F34: 195000 | G34: =J34*Assumption!$B$3 -> 200000 | H34: =J34*Assumption!$B$4 -> 200000 | I34: 10 | J34: =SUM(L34:W34) -> 200 | K34: 10 | S34: 50 | T34: 50 | U34: 50 | V34: 50 | X34: =SUM(Y34:AJ34) -> 220 | Y34: =ROUND(L34*(100+$K34)/100,0) -> 0 | Z34: 0 | AA34: =ROUND(N34*(100+$K34)/100,0) -> 0 | AB34: =ROUND(O34*(100+$K34)/100,0) -> 0 | AC34: =ROUND(P34*(100+$K34)/100,0) -> 0 | AD34: =ROUND(Q34*(100+$K34)/100,0) -> 0 | AE34: =ROUND(R34*(100+$K34)/100,0) -> 0 | AF34: =ROUND(S34*(100+$K34)/100,0) -> 55 | AG34: =ROUND(T34*(100+$K34)/100,0) -> 55 | AH34: =ROUND(U34*(100+$K34)/100,0) -> 55 | ... AJ34: =ROUND(W34*(100+$K34)/100,0) -> 0
A35: SOUTH | B35: Dorset | C35: Dorset | D35: WPD_S | E35: Dorset WP2 | F35: 60000 | G35: =J35*Assumption!$B$3 -> 50000 | H35: =J35*Assumption!$B$4 -> 50000 | I35: 10 | J35: =SUM(L35:W35) -> 50 | K35: 10 | W35: 50 | X35: =SUM(Y35:AJ35) -> 55 | Y35: =ROUND(L35*(100+$K35)/100,0) -> 0 | Z35: 0 | AA35: =ROUND(N35*(100+$K35)/100,0) -> 0 | AB35: =ROUND(O35*(100+$K35)/100,0) -> 0 | AC35: =ROUND(P35*(100+$K35)/100,0) -> 0 | AD35: =ROUND(Q35*(100+$K35)/100,0) -> 0 | AE35: =ROUND(R35*(100+$K35)/100,0) -> 0 | AF35: =ROUND(S35*(100+$K35)/100,0) -> 0 | AG35: =ROUND(T35*(100+$K35)/100,0) -> 0 | AH35: =ROUND(U35*(100+$K35)/100,0) -> 0 | ... AJ35: =ROUND(W35*(100+$K35)/100,0) -> 55
A36: SOUTH | B36: Dorset | C36: Dorset | D36: WPD_S | E36: Dorset WP3 | F36: 0 | G36: =J36*Assumption!$B$3 -> 0 | H36: =J36*Assumption!$B$4 -> 0 | I36: 10 | J36: =SUM(L36:W36) -> 0 | K36: 10 | X36: =SUM(Y36:AJ36) -> 0 | Y36: =ROUND(L36*(100+$K36)/100,0) -> 0 | Z36: 0 | AA36: =ROUND(N36*(100+$K36)/100,0) -> 0 | AB36: =ROUND(O36*(100+$K36)/100,0) -> 0 | AC36: =ROUND(P36*(100+$K36)/100,0) -> 0 | AD36: =ROUND(Q36*(100+$K36)/100,0) -> 0 | AE36: =ROUND(R36*(100+$K36)/100,0) -> 0 | AF36: =ROUND(S36*(100+$K36)/100,0) -> 0 | AG36: =ROUND(T36*(100+$K36)/100,0) -> 0 | AH36: =ROUND(U36*(100+$K36)/100,0) -> 0 | ... AJ36: =ROUND(W36*(100+$K36)/100,0) -> 0
A37: SOUTH | B37: West Sussex | C37: West Sussex | D37: UKPN_SE | E37: West Sussex - Phase 4 WP2 | F37: 132000 | G37: =J37*Assumption!$B$3 -> 250000 | H37: =J37*Assumption!$B$4 -> 250000 | I37: 10 | J37: =SUM(L37:W37) -> 250 | K37: 10 | L37: 50 | N37: 50 | R37: 50 | S37: 50 | T37: 50 | X37: =SUM(Y37:AJ37) -> 275 | Y37: =ROUND(L37*(100+$K37)/100,0) -> 55 | Z37: 0 | AA37: =ROUND(N37*(100+$K37)/100,0) -> 55 | AB37: =ROUND(O37*(100+$K37)/100,0) -> 0 | AC37: =ROUND(P37*(100+$K37)/100,0) -> 0 | AD37: =ROUND(Q37*(100+$K37)/100,0) -> 0 | AE37: =ROUND(R37*(100+$K37)/100,0) -> 55 | AF37: =ROUND(S37*(100+$K37)/100,0) -> 55 | AG37: =ROUND(T37*(100+$K37)/100,0) -> 55 | AH37: =ROUND(U37*(100+$K37)/100,0) -> 0 | ... AJ37: =ROUND(W37*(100+$K37)/100,0) -> 0
A38: SOUTH | B38: Wealden | C38: Wealden | D38: UKPN_SE | E38: Wealden | F38: 18000 | G38: =J38*Assumption!$B$3 -> 100000 | H38: =J38*Assumption!$B$4 -> 100000 | I38: 10 | J38: =SUM(L38:W38) -> 100 | K38: 10 | L38: 50 | N38: 50 | X38: =SUM(Y38:AJ38) -> 110 | Y38: =ROUND(L38*(100+$K38)/100,0) -> 55 | Z38: 0 | AA38: =ROUND(N38*(100+$K38)/100,0) -> 55 | AB38: =ROUND(O38*(100+$K38)/100,0) -> 0 | AC38: =ROUND(P38*(100+$K38)/100,0) -> 0 | AD38: =ROUND(Q38*(100+$K38)/100,0) -> 0 | AE38: =ROUND(R38*(100+$K38)/100,0) -> 0 | AF38: =ROUND(S38*(100+$K38)/100,0) -> 0 | AG38: =ROUND(T38*(100+$K38)/100,0) -> 0 | AH38: =ROUND(U38*(100+$K38)/100,0) -> 0 | ... AJ38: =ROUND(W38*(100+$K38)/100,0) -> 0
A39: SOUTH | B39: Havering | C39: Havering | D39: UKPN_LPN | E39: Havering | F39: 33000 | G39: =J39*Assumption!$B$3 -> 100000 | H39: =J39*Assumption!$B$4 -> 100000 | I39: 10 | J39: =SUM(L39:W39) -> 100 | K39: 10 | M39: 50 | O39: 50 | X39: =SUM(Y39:AJ39) -> 68 | Y39: =ROUND(L39*(100+$K39)/100,0) -> 0 | Z39: 13 | AA39: =ROUND(N39*(100+$K39)/100,0) -> 0 | AB39: =ROUND(O39*(100+$K39)/100,0) -> 55 | AC39: =ROUND(P39*(100+$K39)/100,0) -> 0 | AD39: =ROUND(Q39*(100+$K39)/100,0) -> 0 | AE39: =ROUND(R39*(100+$K39)/100,0) -> 0 | AF39: =ROUND(S39*(100+$K39)/100,0) -> 0 | AG39: =ROUND(T39*(100+$K39)/100,0) -> 0 | AH39: =ROUND(U39*(100+$K39)/100,0) -> 0 | ... AJ39: =ROUND(W39*(100+$K39)/100,0) -> 0
A40: SOUTH | B40: Dorset - LEVI Pilot WP1 | C40: Dorset - LEVI Pilot WP1 | D40: WPD_S | E40: Dorset - LEVI Pilot WP1 | F40: 90000 | G40: =J40*Assumption!$B$3 -> 50000 | H40: =J40*Assumption!$B$4 -> 50000 | I40: 10 | J40: =SUM(L40:W40) -> 50 | K40: 10 | R40: 50 | X40: =SUM(Y40:AJ40) -> 55 | Y40: =ROUND(L40*(100+$K40)/100,0) -> 0 | Z40: 0 | AA40: =ROUND(N40*(100+$K40)/100,0) -> 0 | AB40: =ROUND(O40*(100+$K40)/100,0) -> 0 | AC40: =ROUND(P40*(100+$K40)/100,0) -> 0 | AD40: =ROUND(Q40*(100+$K40)/100,0) -> 0 | AE40: =ROUND(R40*(100+$K40)/100,0) -> 55 | AF40: =ROUND(S40*(100+$K40)/100,0) -> 0 | AG40: =ROUND(T40*(100+$K40)/100,0) -> 0 | AH40: =ROUND(U40*(100+$K40)/100,0) -> 0 | ... AJ40: =ROUND(W40*(100+$K40)/100,0) -> 0
...

Sheet Assumption
A1: Value per socket | B1: Assumption | C1: Notes
A2: capex_bom | B2: 1000 | C2: Bill of Materials
A3: capex_installation | B3: 1000 | C3: On‑site build cost
A4: capex_connection | B4: 1000 | C4: Getting power to site, include ICP (Independent Connection Provider) and DNO cost
A5: capex | B5: =SUM(B2:B4) -> 3000
A6: Asset Value | B6: 1000
B8: No. of sockets
A9: Senior Delivery Manager annual capacity | B9: 1000
A10: Delivery Manger annual capacity | B10: 500
