Workbook

Sheet Sheet1
A1: region_name | B1: contract_name | C1: work_package_name | D1: capex_bom_per_socket | E1: capex_installation_per_socket | F1: capex_connection_per_socket | G1: total_capex_per_socket | H1: target_sockets | I1: target_sockets_1 | J1: target_sockets_2 | K1: target_sockets_3 | L1: target_sockets_4 | M1: target_sockets_5 | N1: target_sockets_6 | O1: target_sockets_7 | P1: target_sockets_8 | Q1: target_sockets_9 | R1: target_sockets_10 | S1: target_sockets_11 | T1: target_sockets_12
A2: SOUTH | B2: Surrey | C2: Surrey WP10 | D2: =Assumption!$B$2 -> 1000 | E2: =Assumption!$B$3 -> 1000 | F2: =Assumption!$B$4 -> 1000 | G2: =SUM(D2:F2) -> 3000 | H2: =SUM(I2:T2) -> 150 | I2: 50 | J2: 50 | K2: 50
A3: SOUTH | B3: Surrey | C3: Surrey WP11 | D3: =Assumption!$B$2 -> 1000 | E3: =Assumption!$B$3 -> 1000 | F3: =Assumption!$B$4 -> 1000 | G3: =SUM(D3:F3) -> 3000 | H3: =SUM(I3:T3) -> 100 | M3: 50 | N3: 50
A4: SOUTH | B4: Surrey | C4: Surrey WP12 | D4: =Assumption!$B$2 -> 1000 | E4: =Assumption!$B$3 -> 1000 | F4: =Assumption!$B$4 -> 1000 | G4: =SUM(D4:F4) -> 3000 | H4: =SUM(I4:T4) -> 100 | N4: 50 | O4: 50
A5: SOUTH | B5: Surrey | C5: Surrey WP13 | D5: =Assumption!$B$2 -> 1000 | E5: =Assumption!$B$3 -> 1000 | F5: =Assumption!$B$4 -> 1000 | G5: =SUM(D5:F5) -> 3000 | H5: =SUM(I5:T5) -> 100 | O5: 50 | P5: 50
A6: SOUTH | B6: Surrey | C6: Surrey WP14 | D6: =Assumption!$B$2 -> 1000 | E6: =Assumption!$B$3 -> 1000 | F6: =Assumption!$B$4 -> 1000 | G6: =SUM(D6:F6) -> 3000 | H6: =SUM(I6:T6) -> 100 | P6: 50 | Q6: 50
A7: SOUTH | B7: Surrey | C7: Surrey WP15 | D7: =Assumption!$B$2 -> 1000 | E7: =Assumption!$B$3 -> 1000 | F7: =Assumption!$B$4 -> 1000 | G7: =SUM(D7:F7) -> 3000 | H7: =SUM(I7:T7) -> 100 | R7: 50 | S7: 50
A8: SOUTH | B8: Surrey | C8: Surrey WP16 | D8: =Assumption!$B$2 -> 1000 | E8: =Assumption!$B$3 -> 1000 | F8: =Assumption!$B$4 -> 1000 | G8: =SUM(D8:F8) -> 3000 | H8: =SUM(I8:T8) -> 50 | T8: 50
A9: SOUTH | B9: Surrey | C9: Surrey WP17 | D9: =Assumption!$B$2 -> 1000 | E9: =Assumption!$B$3 -> 1000 | F9: =Assumption!$B$4 -> 1000 | G9: =SUM(D9:F9) -> 3000 | H9: =SUM(I9:T9) -> 0
A10: SOUTH | B10: Surrey | C10: Surrey WP18 | D10: =Assumption!$B$2 -> 1000 | E10: =Assumption!$B$3 -> 1000 | F10: =Assumption!$B$4 -> 1000 | G10: =SUM(D10:F10) -> 3000 | H10: =SUM(I10:T10) -> 0
A11: SOUTH | B11: Surrey | C11: Surrey WP19 | D11: =Assumption!$B$2 -> 1000 | E11: =Assumption!$B$3 -> 1000 | F11: =Assumption!$B$4 -> 1000 | G11: =SUM(D11:F11) -> 3000 | H11: =SUM(I11:T11) -> 0
A12: SOUTH | B12: Surrey | C12: Surrey WP20 | D12: =Assumption!$B$2 -> 1000 | E12: =Assumption!$B$3 -> 1000 | F12: =Assumption!$B$4 -> 1000 | G12: =SUM(D12:F12) -> 3000 | H12: =SUM(I12:T12) -> 0
A13: SOUTH | B13: Surrey | C13: Surrey WP21 | D13: =Assumption!$B$2 -> 1000 | E13: =Assumption!$B$3 -> 1000 | F13: =Assumption!$B$4 -> 1000 | G13: =SUM(D13:F13) -> 3000 | H13: =SUM(I13:T13) -> 0
A14: SOUTH | B14: Surrey | C14: Surrey WP22 | D14: =Assumption!$B$2 -> 1000 | E14: =Assumption!$B$3 -> 1000 | F14: =Assumption!$B$4 -> 1000 | G14: =SUM(D14:F14) -> 3000 | H14: =SUM(I14:T14) -> 0
A15: SOUTH | B15: Surrey LP | C15: Surrey Lamppost WP1 | D15: =Assumption!$B$2 -> 1000 | E15: =Assumption!$B$3 -> 1000 | F15: =Assumption!$B$4 -> 1000 | G15: =SUM(D15:F15) -> 3000 | H15: =SUM(I15:T15) -> 100 | L15: 50 | M15: 50
A16: SOUTH | B16: Surrey LP | C16: Surrey Lamppost WP2 | D16: =Assumption!$B$2 -> 1000 | E16: =Assumption!$B$3 -> 1000 | F16: =Assumption!$B$4 -> 1000 | G16: =SUM(D16:F16) -> 3000 | H16: =SUM(I16:T16) -> 300 | N16: 50 | O16: 50 | P16: 50 | Q16: 50 | R16: 50 | S16: 50
A17: SOUTH | B17: Surrey LP | C17: Surrey Lamppost WP3 | D17: =Assumption!$B$2 -> 1000 | E17: =Assumption!$B$3 -> 1000 | F17: =Assumption!$B$4 -> 1000 | G17: =SUM(D17:F17) -> 3000 | H17: =SUM(I17:T17) -> 100 | N17: 50 | O17: 50
A18: SOUTH | B18: Surrey LP | C18: Surrey Lamppost WP4 | D18: =Assumption!$B$2 -> 1000 | E18: =Assumption!$B$3 -> 1000 | F18: =Assumption!$B$4 -> 1000 | G18: =SUM(D18:F18) -> 3000 | H18: =SUM(I18:T18) -> 100 | O18: 50 | P18: 50
A19: SOUTH | B19: Surrey LP | C19: Surrey Lamppost WP5 | D19: =Assumption!$B$2 -> 1000 | E19: =Assumption!$B$3 -> 1000 | F19: =Assumption!$B$4 -> 1000 | G19: =SUM(D19:F19) -> 3000 | H19: =SUM(I19:T19) -> 100 | P19: 50 | Q19: 50
A20: SOUTH | B20: Surrey LP | C20: Surrey Lamppost WP6 | D20: =Assumption!$B$2 -> 1000 | E20: =Assumption!$B$3 -> 1000 | F20: =Assumption!$B$4 -> 1000 | G20: =SUM(D20:F20) -> 3000 | H20: =SUM(I20:T20) -> 100 | Q20: 50 | R20: 50
A21: SOUTH | B21: Surrey LP | C21: Surrey Lamppost WP7 | D21: =Assumption!$B$2 -> 1000 | E21: =Assumption!$B$3 -> 1000 | F21: =Assumption!$B$4 -> 1000 | G21: =SUM(D21:F21) -> 3000 | H21: =SUM(I21:T21) -> 100 | R21: 50 | S21: 50
A22: SOUTH | B22: Surrey LP | C22: Surrey Lamppost WP8 | D22: =Assumption!$B$2 -> 1000 | E22: =Assumption!$B$3 -> 1000 | F22: =Assumption!$B$4 -> 1000 | G22: =SUM(D22:F22) -> 3000 | H22: =SUM(I22:T22) -> 100 | S22: 50 | T22: 50
A23: SOUTH | B23: Surrey LP | C23: Surrey Lamppost WP9 | D23: =Assumption!$B$2 -> 1000 | E23: =Assumption!$B$3 -> 1000 | F23: =Assumption!$B$4 -> 1000 | G23: =SUM(D23:F23) -> 3000 | H23: =SUM(I23:T23) -> 50 | T23: 50
A24: SOUTH | B24: Surrey LP | C24: Surrey Lamppost WP10 | D24: =Assumption!$B$2 -> 1000 | E24: =Assumption!$B$3 -> 1000 | F24: =Assumption!$B$4 -> 1000 | G24: =SUM(D24:F24) -> 3000 | H24: =SUM(I24:T24) -> 0
A25: SOUTH | B25: Surrey LP | C25: Surrey Lamppost WP11 | D25: =Assumption!$B$2 -> 1000 | E25: =Assumption!$B$3 -> 1000 | F25: =Assumption!$B$4 -> 1000 | G25: =SUM(D25:F25) -> 3000 | H25: =SUM(I25:T25) -> 0
A26: SOUTH | B26: Plymouth | C26: Plymouth WP1 | D26: =Assumption!$B$2 -> 1000 | E26: =Assumption!$B$3 -> 1000 | F26: =Assumption!$B$4 -> 1000 | G26: =SUM(D26:F26) -> 3000 | H26: =SUM(I26:T26) -> 50 | I26: 0 | J26: 0 | K26: 0 | L26: 50 | M26: 0 | N26: 0 | O26: 0 | P26: 0 | Q26: 0 | R26: 0 | S26: 0 | T26: 0
A27: SOUTH | B27: Plymouth | C27: Plymouth WP2 | D27: =Assumption!$B$2 -> 1000 | E27: =Assumption!$B$3 -> 1000 | F27: =Assumption!$B$4 -> 1000 | G27: =SUM(D27:F27) -> 3000 | H27: =SUM(I27:T27) -> 100 | I27: 0 | J27: 0 | K27: 0 | L27: 0 | M27: 50 | N27: 50 | O27: 0 | P27: 0 | Q27: 0 | R27: 0 | S27: 0 | T27: 0
A28: SOUTH | B28: Plymouth | C28: Plymouth WP3 | D28: =Assumption!$B$2 -> 1000 | E28: =Assumption!$B$3 -> 1000 | F28: =Assumption!$B$4 -> 1000 | G28: =SUM(D28:F28) -> 3000 | H28: =SUM(I28:T28) -> 150 | I28: 0 | J28: 0 | K28: 0 | L28: 0 | M28: 0 | N28: 0 | O28: 50 | P28: 50 | Q28: 50 | R28: 0 | S28: 0 | T28: 0
A29: SOUTH | B29: Plymouth | C29: Plymouth WP4 | D29: =Assumption!$B$2 -> 1000 | E29: =Assumption!$B$3 -> 1000 | F29: =Assumption!$B$4 -> 1000 | G29: =SUM(D29:F29) -> 3000 | H29: =SUM(I29:T29) -> 150 | I29: 0 | J29: 0 | K29: 0 | L29: 0 | M29: 0 | N29: 0 | O29: 0 | P29: 0 | Q29: 50 | R29: 50 | S29: 50 | T29: 0
A30: SOUTH | B30: Plymouth | C30: Plymouth WP5 | D30: =Assumption!$B$2 -> 1000 | E30: =Assumption!$B$3 -> 1000 | F30: =Assumption!$B$4 -> 1000 | G30: =SUM(D30:F30) -> 3000 | H30: =SUM(I30:T30) -> 50 | I30: 0 | J30: 0 | K30: 0 | L30: 0 | M30: 0 | N30: 0 | O30: 0 | P30: 0 | Q30: 0 | R30: 0 | S30: 0 | T30: 50
A31: SOUTH | B31: Bournemouth, Christchurch & Poole | C31: Bournemouth, Christchurch and Poole WP1 | D31: =Assumption!$B$2 -> 1000 | E31: =Assumption!$B$3 -> 1000 | F31: =Assumption!$B$4 -> 1000 | G31: =SUM(D31:F31) -> 3000 | H31: =SUM(I31:T31) -> 200 | Q31: 50 | R31: 50 | S31: 50 | T31: 50
A32: SOUTH | B32: Bournemouth, Christchurch & Poole | C32: Bournemouth, Christchurch and Poole WP2 | D32: =Assumption!$B$2 -> 1000 | E32: =Assumption!$B$3 -> 1000 | F32: =Assumption!$B$4 -> 1000 | G32: =SUM(D32:F32) -> 3000 | H32: =SUM(I32:T32) -> 0
A33: SOUTH | B33: Bournemouth, Christchurch & Poole | C33: Bournemouth, Christchurch and Poole WP3 | D33: =Assumption!$B$2 -> 1000 | E33: =Assumption!$B$3 -> 1000 | F33: =Assumption!$B$4 -> 1000 | G33: =SUM(D33:F33) -> 3000 | H33: =SUM(I33:T33) -> 0
A34: SOUTH | B34: Dorset | C34: Dorset WP1 | D34: =Assumption!$B$2 -> 1000 | E34: =Assumption!$B$3 -> 1000 | F34: =Assumption!$B$4 -> 1000 | G34: =SUM(D34:F34) -> 3000 | H34: =SUM(I34:T34) -> 200 | P34: 50 | Q34: 50 | R34: 50 | S34: 50
A35: SOUTH | B35: Dorset | C35: Dorset WP2 | D35: =Assumption!$B$2 -> 1000 | E35: =Assumption!$B$3 -> 1000 | F35: =Assumption!$B$4 -> 1000 | G35: =SUM(D35:F35) -> 3000 | H35: =SUM(I35:T35) -> 50 | T35: 50
A36: SOUTH | B36: Dorset | C36: Dorset WP3 | D36: =Assumption!$B$2 -> 1000 | E36: =Assumption!$B$3 -> 1000 | F36: =Assumption!$B$4 -> 1000 | G36: =SUM(D36:F36) -> 3000 | H36: =SUM(I36:T36) -> 0
A37: SOUTH | B37: West Sussex | C37: West Sussex - Phase 4 WP2 | D37: =Assumption!$B$2 -> 1000 | E37: =Assumption!$B$3 -> 1000 | F37: =Assumption!$B$4 -> 1000 | G37: =SUM(D37:F37) -> 3000 | H37: =SUM(I37:T37) -> 250 | I37: 50 | K37: 50 | O37: 50 | P37: 50 | Q37: 50
A38: SOUTH | B38: Wealden | C38: Wealden | D38: =Assumption!$B$2 -> 1000 | E38: =Assumption!$B$3 -> 1000 | F38: =Assumption!$B$4 -> 1000 | G38: =SUM(D38:F38) -> 3000 | H38: =SUM(I38:T38) -> 100 | I38: 50 | K38: 50
A39: SOUTH | B39: Havering | C39: Havering | D39: =Assumption!$B$2 -> 1000 | E39: =Assumption!$B$3 -> 1000 | F39: =Assumption!$B$4 -> 1000 | G39: =SUM(D39:F39) -> 3000 | H39: =SUM(I39:T39) -> 100 | J39: 50 | L39: 50
A40: SOUTH | B40: Dorset - LEVI Pilot WP1 | C40: Dorset - LEVI Pilot WP1 | D40: =Assumption!$B$2 -> 1000 | E40: =Assumption!$B$3 -> 1000 | F40: =Assumption!$B$4 -> 1000 | G40: =SUM(D40:F40) -> 3000 | H40: =SUM(I40:T40) -> 50 | O40: 50
...

Sheet Capex Calculation
A1: BOM
A2: month 1 | B2: month 2 | C2: month 3 | D2: month 4 | E2: month 5 | F2: month 6 | G2: month 7 | H2: month 8 | I2: month 9 | J2: month 10 | K2: month 11 | L2: month 12

Sheet Assumption
A1: Value per socket | B1: Assumption | C1: Notes
A2: capex_bom | B2: 1000 | C2: Bill of Materials
A3: capex_installation | B3: 1000 | C3: On‑site build cost
A4: capex_connection | B4: 1000 | C4: Getting power to site, include ICP (Independent Connection Provider) and DNO cost
A5: capex | B5: =SUM(B2:B4) -> 3000
A6: Asset Value | B6: 1000
B8: No. of sockets
A9: Senior Delivery Manager annual capacity | B9: 1000
A10: Delivery Manger annual capacity | B10: 500
